{"name": "test_mul[错误样例]", "status": "failed", "statusDetails": {"message": "AssertionError: assert 4 == -3", "trace": "self = <pytest_practice.testing.test_calculator_second.TestCalculator object at 0x111909110>, get_cal = <pytest_practice.pythoncode.calculator.Calculator object at 0x1118a0710>, start_cal = None, get_mul = [3, -1, 4]\n\n        @pytest.mark.mul\n    #    @pytest.mark.run(order=2)\n        @pytest.mark.third\n        def test_mul(self,get_cal,start_cal,get_mul):\n            result = get_cal.mul(get_mul[0],get_mul[1])\n>           assert get_mul[2] == result\nE           assert 4 == -3\n\ntest_calculator_second.py:38: AssertionError"}, "attachments": [{"name": "stdout", "source": "41861936-a4d4-4ded-9d48-eea52f77d482-attachment.txt", "type": "text/plain"}], "parameters": [{"name": "get_mul", "value": "[3, -1, 4]"}], "start": 1599554105413, "stop": 1599554105414, "uuid": "07156b6a-913e-455c-afe2-8607fe9c9ed2", "historyId": "4eac8e75f8a950e2694cf20077593257", "testCaseId": "9a4810beca7dfaf62790aa530e4a8327", "fullName": "pytest_practice.testing.test_calculator_second.TestCalculator#test_mul", "labels": [{"name": "tag", "value": "mul"}, {"name": "tag", "value": "run(order=2)"}, {"name": "tag", "value": "third"}, {"name": "parentSuite", "value": "pytest_practice.testing"}, {"name": "suite", "value": "test_calculator_second"}, {"name": "subSuite", "value": "TestCalculator"}, {"name": "host", "value": "localhost"}, {"name": "thread", "value": "17558-MainThread"}, {"name": "framework", "value": "pytest"}, {"name": "language", "value": "cpython3"}, {"name": "package", "value": "pytest_practice.testing.test_calculator_second"}]}