{"name": "test_add[错误样例]", "status": "failed", "statusDetails": {"message": "AssertionError: assert 4 == 2", "trace": "self = <pytest_practice.testing.test_calculator_second.TestCalculator object at 0x1118cc8d0>, get_cal = <pytest_practice.pythoncode.calculator.Calculator object at 0x1118a0710>, start_cal = None, get_add = [3, -1, 4]\n\n        @pytest.mark.add\n    #    @pytest.mark.run(order=0)\n        @pytest.mark.first\n        def test_add(self,get_cal,start_cal,get_add):\n            if type(get_add[0]) is float or type(get_add[1]) is float:\n                result = round(get_cal.add(get_add[0],get_add[1]),2)\n            else:\n                result = get_cal.add(get_add[0], get_add[1])\n>           assert get_add[2] == result\nE           assert 4 == 2\n\ntest_calculator_second.py:13: AssertionError"}, "attachments": [{"name": "stdout", "source": "83c3fffa-d60f-4e80-9436-37cbcf940db3-attachment.txt", "type": "text/plain"}], "parameters": [{"name": "get_add", "value": "[3, -1, 4]"}], "start": 1599554105282, "stop": 1599554105282, "uuid": "dedddc87-33b6-495e-aea2-18ed73da8c30", "historyId": "46ba8295279658ac5ba1e7e65c890174", "testCaseId": "6d7a7b78ae8f2f9fa5936089c3d7d31d", "fullName": "pytest_practice.testing.test_calculator_second.TestCalculator#test_add", "labels": [{"name": "tag", "value": "run(order=0)"}, {"name": "tag", "value": "first"}, {"name": "tag", "value": "add"}, {"name": "parentSuite", "value": "pytest_practice.testing"}, {"name": "suite", "value": "test_calculator_second"}, {"name": "subSuite", "value": "TestCalculator"}, {"name": "host", "value": "localhost"}, {"name": "thread", "value": "17558-MainThread"}, {"name": "framework", "value": "pytest"}, {"name": "language", "value": "cpython3"}, {"name": "package", "value": "pytest_practice.testing.test_calculator_second"}]}